[2023-11-29T13:03:22.204+0000] {taskinstance.py:1083} INFO - Dependencies all met for <TaskInstance: football-etl.extract_matches scheduled__2023-01-15T00:00:00+00:00 [queued]>
[2023-11-29T13:03:22.214+0000] {taskinstance.py:1083} INFO - Dependencies all met for <TaskInstance: football-etl.extract_matches scheduled__2023-01-15T00:00:00+00:00 [queued]>
[2023-11-29T13:03:22.215+0000] {taskinstance.py:1279} INFO - 
--------------------------------------------------------------------------------
[2023-11-29T13:03:22.216+0000] {taskinstance.py:1280} INFO - Starting attempt 1 of 2
[2023-11-29T13:03:22.216+0000] {taskinstance.py:1281} INFO - 
--------------------------------------------------------------------------------
[2023-11-29T13:03:22.231+0000] {taskinstance.py:1300} INFO - Executing <Task(PythonOperator): extract_matches> on 2023-01-15 00:00:00+00:00
[2023-11-29T13:03:22.239+0000] {standard_task_runner.py:55} INFO - Started process 827 to run task
[2023-11-29T13:03:22.242+0000] {standard_task_runner.py:82} INFO - Running: ['***', 'tasks', 'run', 'football-etl', 'extract_matches', 'scheduled__2023-01-15T00:00:00+00:00', '--job-id', '58', '--raw', '--subdir', 'DAGS_FOLDER/dag-football.py', '--cfg-path', '/tmp/tmpyq3qz02t']
[2023-11-29T13:03:22.242+0000] {standard_task_runner.py:83} INFO - Job 58: Subtask extract_matches
[2023-11-29T13:03:22.504+0000] {task_command.py:388} INFO - Running <TaskInstance: football-etl.extract_matches scheduled__2023-01-15T00:00:00+00:00 [running]> on host 6377c365460c
[2023-11-29T13:03:22.566+0000] {taskinstance.py:1509} INFO - Exporting the following env vars:
AIRFLOW_CTX_DAG_OWNER=***
AIRFLOW_CTX_DAG_ID=football-etl
AIRFLOW_CTX_TASK_ID=extract_matches
AIRFLOW_CTX_EXECUTION_DATE=2023-01-15T00:00:00+00:00
AIRFLOW_CTX_TRY_NUMBER=1
AIRFLOW_CTX_DAG_RUN_ID=scheduled__2023-01-15T00:00:00+00:00
[2023-11-29T13:03:26.572+0000] {extract_matches.py:14} ERROR - Error Connecting: HTTPSConnectionPool(host='api.football-data.org', port=443): Max retries exceeded with url: /v4/competitions/PL/matches?season=2023 (Caused by NewConnectionError('<urllib3.connection.HTTPSConnection object at 0x7f0470687550>: Failed to establish a new connection: [Errno -3] Temporary failure in name resolution'))
[2023-11-29T13:03:26.573+0000] {taskinstance.py:1768} ERROR - Task failed with exception
Traceback (most recent call last):
  File "/home/airflow/.local/lib/python3.7/site-packages/airflow/operators/python.py", line 175, in execute
    return_value = self.execute_callable()
  File "/home/airflow/.local/lib/python3.7/site-packages/airflow/operators/python.py", line 192, in execute_callable
    return self.python_callable(*self.op_args, **self.op_kwargs)
  File "/opt/airflow/dags/script/extract_matches.py", line 77, in extract_matches
    extracted_df = extract_api_matches(api_key)
  File "/opt/airflow/dags/script/extract_matches.py", line 62, in extract_api_matches
    response = make_api_request(url, headers, params)
  File "/opt/airflow/dags/script/extract_matches.py", line 19, in make_api_request
    return response
UnboundLocalError: local variable 'response' referenced before assignment
[2023-11-29T13:03:26.588+0000] {taskinstance.py:1323} INFO - Marking task as UP_FOR_RETRY. dag_id=football-etl, task_id=extract_matches, execution_date=20230115T000000, start_date=20231129T130322, end_date=20231129T130326
[2023-11-29T13:03:26.602+0000] {standard_task_runner.py:105} ERROR - Failed to execute job 58 for task extract_matches (local variable 'response' referenced before assignment; 827)
[2023-11-29T13:03:26.628+0000] {local_task_job.py:208} INFO - Task exited with return code 1
[2023-11-29T13:03:26.841+0000] {taskinstance.py:2578} INFO - 0 downstream tasks scheduled from follow-on schedule check
