[2023-11-29T14:04:12.718+0000] {taskinstance.py:1083} INFO - Dependencies all met for <TaskInstance: football-etl.extract_market_value scheduled__2023-02-25T00:00:00+00:00 [queued]>
[2023-11-29T14:04:12.737+0000] {taskinstance.py:1083} INFO - Dependencies all met for <TaskInstance: football-etl.extract_market_value scheduled__2023-02-25T00:00:00+00:00 [queued]>
[2023-11-29T14:04:12.738+0000] {taskinstance.py:1279} INFO - 
--------------------------------------------------------------------------------
[2023-11-29T14:04:12.739+0000] {taskinstance.py:1280} INFO - Starting attempt 1 of 2
[2023-11-29T14:04:12.739+0000] {taskinstance.py:1281} INFO - 
--------------------------------------------------------------------------------
[2023-11-29T14:04:12.980+0000] {taskinstance.py:1300} INFO - Executing <Task(PythonOperator): extract_market_value> on 2023-02-25 00:00:00+00:00
[2023-11-29T14:04:12.988+0000] {standard_task_runner.py:55} INFO - Started process 3675 to run task
[2023-11-29T14:04:12.992+0000] {standard_task_runner.py:82} INFO - Running: ['***', 'tasks', 'run', 'football-etl', 'extract_market_value', 'scheduled__2023-02-25T00:00:00+00:00', '--job-id', '262', '--raw', '--subdir', 'DAGS_FOLDER/dag-football.py', '--cfg-path', '/tmp/tmptyanawwz']
[2023-11-29T14:04:12.993+0000] {standard_task_runner.py:83} INFO - Job 262: Subtask extract_market_value
[2023-11-29T14:04:13.354+0000] {task_command.py:388} INFO - Running <TaskInstance: football-etl.extract_market_value scheduled__2023-02-25T00:00:00+00:00 [running]> on host 6377c365460c
[2023-11-29T14:04:23.882+0000] {taskinstance.py:1768} ERROR - Task failed with exception
Traceback (most recent call last):
  File "/home/airflow/.local/lib/python3.7/site-packages/sqlalchemy/engine/base.py", line 1089, in _commit_impl
    self.engine.dialect.do_commit(self.connection)
  File "/home/airflow/.local/lib/python3.7/site-packages/sqlalchemy/engine/default.py", line 686, in do_commit
    dbapi_connection.commit()
psycopg2.OperationalError: server closed the connection unexpectedly
	This probably means the server terminated abnormally
	before or while processing the request.


The above exception was the direct cause of the following exception:

Traceback (most recent call last):
  File "/home/airflow/.local/lib/python3.7/site-packages/airflow/models/taskinstance.py", line 1374, in _run_raw_task
    self._execute_task_with_callbacks(context, test_mode)
  File "/home/airflow/.local/lib/python3.7/site-packages/airflow/models/taskinstance.py", line 1496, in _execute_task_with_callbacks
    RenderedTaskInstanceFields.write(rtif)
  File "/home/airflow/.local/lib/python3.7/site-packages/airflow/utils/session.py", line 75, in wrapper
    return func(*args, session=session, **kwargs)
  File "/usr/local/lib/python3.7/contextlib.py", line 119, in __exit__
    next(self.gen)
  File "/home/airflow/.local/lib/python3.7/site-packages/airflow/utils/session.py", line 36, in create_session
    session.commit()
  File "/home/airflow/.local/lib/python3.7/site-packages/sqlalchemy/orm/session.py", line 1451, in commit
    self._transaction.commit(_to_root=self.future)
  File "/home/airflow/.local/lib/python3.7/site-packages/sqlalchemy/orm/session.py", line 836, in commit
    trans.commit()
  File "/home/airflow/.local/lib/python3.7/site-packages/sqlalchemy/engine/base.py", line 2459, in commit
    self._do_commit()
  File "/home/airflow/.local/lib/python3.7/site-packages/sqlalchemy/engine/base.py", line 2649, in _do_commit
    self._connection_commit_impl()
  File "/home/airflow/.local/lib/python3.7/site-packages/sqlalchemy/engine/base.py", line 2620, in _connection_commit_impl
    self.connection._commit_impl()
  File "/home/airflow/.local/lib/python3.7/site-packages/sqlalchemy/engine/base.py", line 1091, in _commit_impl
    self._handle_dbapi_exception(e, None, None, None, None)
  File "/home/airflow/.local/lib/python3.7/site-packages/sqlalchemy/engine/base.py", line 2125, in _handle_dbapi_exception
    sqlalchemy_exception, with_traceback=exc_info[2], from_=e
  File "/home/airflow/.local/lib/python3.7/site-packages/sqlalchemy/util/compat.py", line 211, in raise_
    raise exception
  File "/home/airflow/.local/lib/python3.7/site-packages/sqlalchemy/engine/base.py", line 1089, in _commit_impl
    self.engine.dialect.do_commit(self.connection)
  File "/home/airflow/.local/lib/python3.7/site-packages/sqlalchemy/engine/default.py", line 686, in do_commit
    dbapi_connection.commit()
sqlalchemy.exc.OperationalError: (psycopg2.OperationalError) server closed the connection unexpectedly
	This probably means the server terminated abnormally
	before or while processing the request.

(Background on this error at: https://sqlalche.me/e/14/e3q8)
