[2023-11-29T13:02:51.666+0000] {taskinstance.py:1083} INFO - Dependencies all met for <TaskInstance: football-etl.extract_matches scheduled__2023-01-01T00:00:00+00:00 [queued]>
[2023-11-29T13:02:52.146+0000] {taskinstance.py:1083} INFO - Dependencies all met for <TaskInstance: football-etl.extract_matches scheduled__2023-01-01T00:00:00+00:00 [queued]>
[2023-11-29T13:02:52.147+0000] {taskinstance.py:1279} INFO - 
--------------------------------------------------------------------------------
[2023-11-29T13:02:52.149+0000] {taskinstance.py:1280} INFO - Starting attempt 1 of 2
[2023-11-29T13:02:52.150+0000] {taskinstance.py:1281} INFO - 
--------------------------------------------------------------------------------
[2023-11-29T13:02:52.190+0000] {taskinstance.py:1300} INFO - Executing <Task(PythonOperator): extract_matches> on 2023-01-01 00:00:00+00:00
[2023-11-29T13:02:52.208+0000] {standard_task_runner.py:55} INFO - Started process 204 to run task
[2023-11-29T13:02:52.215+0000] {standard_task_runner.py:82} INFO - Running: ['***', 'tasks', 'run', 'football-etl', 'extract_matches', 'scheduled__2023-01-01T00:00:00+00:00', '--job-id', '17', '--raw', '--subdir', 'DAGS_FOLDER/dag-football.py', '--cfg-path', '/tmp/tmpgxb2ef8u']
[2023-11-29T13:02:52.218+0000] {standard_task_runner.py:83} INFO - Job 17: Subtask extract_matches
[2023-11-29T13:02:52.481+0000] {task_command.py:388} INFO - Running <TaskInstance: football-etl.extract_matches scheduled__2023-01-01T00:00:00+00:00 [running]> on host 6377c365460c
[2023-11-29T13:02:52.661+0000] {taskinstance.py:1509} INFO - Exporting the following env vars:
AIRFLOW_CTX_DAG_OWNER=***
AIRFLOW_CTX_DAG_ID=football-etl
AIRFLOW_CTX_TASK_ID=extract_matches
AIRFLOW_CTX_EXECUTION_DATE=2023-01-01T00:00:00+00:00
AIRFLOW_CTX_TRY_NUMBER=1
AIRFLOW_CTX_DAG_RUN_ID=scheduled__2023-01-01T00:00:00+00:00
[2023-11-29T13:02:55.039+0000] {extract_matches.py:55} ERROR - Error occurred while exporting data to CSV: [Errno 2] No such file or directory: 'files/match_data.csv'
[2023-11-29T13:02:55.041+0000] {taskinstance.py:1768} ERROR - Task failed with exception
Traceback (most recent call last):
  File "/home/airflow/.local/lib/python3.7/site-packages/airflow/operators/python.py", line 175, in execute
    return_value = self.execute_callable()
  File "/home/airflow/.local/lib/python3.7/site-packages/airflow/operators/python.py", line 192, in execute_callable
    return self.python_callable(*self.op_args, **self.op_kwargs)
  File "/opt/airflow/dags/script/extract_matches.py", line 82, in extract_matches
    print(pd.read_csv("files/match_data.csv"))
  File "/home/airflow/.local/lib/python3.7/site-packages/pandas/util/_decorators.py", line 311, in wrapper
    return func(*args, **kwargs)
  File "/home/airflow/.local/lib/python3.7/site-packages/pandas/io/parsers/readers.py", line 586, in read_csv
    return _read(filepath_or_buffer, kwds)
  File "/home/airflow/.local/lib/python3.7/site-packages/pandas/io/parsers/readers.py", line 482, in _read
    parser = TextFileReader(filepath_or_buffer, **kwds)
  File "/home/airflow/.local/lib/python3.7/site-packages/pandas/io/parsers/readers.py", line 811, in __init__
    self._engine = self._make_engine(self.engine)
  File "/home/airflow/.local/lib/python3.7/site-packages/pandas/io/parsers/readers.py", line 1040, in _make_engine
    return mapping[engine](self.f, **self.options)  # type: ignore[call-arg]
  File "/home/airflow/.local/lib/python3.7/site-packages/pandas/io/parsers/c_parser_wrapper.py", line 51, in __init__
    self._open_handles(src, kwds)
  File "/home/airflow/.local/lib/python3.7/site-packages/pandas/io/parsers/base_parser.py", line 229, in _open_handles
    errors=kwds.get("encoding_errors", "strict"),
  File "/home/airflow/.local/lib/python3.7/site-packages/pandas/io/common.py", line 707, in get_handle
    newline="",
FileNotFoundError: [Errno 2] No such file or directory: 'files/match_data.csv'
[2023-11-29T13:02:55.055+0000] {taskinstance.py:1323} INFO - Marking task as UP_FOR_RETRY. dag_id=football-etl, task_id=extract_matches, execution_date=20230101T000000, start_date=20231129T130251, end_date=20231129T130255
[2023-11-29T13:02:55.069+0000] {standard_task_runner.py:105} ERROR - Failed to execute job 17 for task extract_matches ([Errno 2] No such file or directory: 'files/match_data.csv'; 204)
[2023-11-29T13:02:55.092+0000] {local_task_job.py:208} INFO - Task exited with return code 1
[2023-11-29T13:02:55.122+0000] {taskinstance.py:2578} INFO - 0 downstream tasks scheduled from follow-on schedule check
